<?xml version="1.0" ?>
<robot name="mbot">

    <link name="base_link">
        <visual>
            <origin xyz=" 0 0 0" rpy="0 0 0" />
            <geometry>
                <box size="0.5 0.37 0.17" />
            </geometry>
            <material name="blue">
                <color rgba="0 0.5 0.9 1"/>
            </material>
        </visual>
    </link>

    <joint name="left_front_wheel_joint" type="continuous">
        <origin xyz="0.19 0.19 -0.05" rpy="0 0 0"/>
        <parent link="base_link"/>
        <child link="left_front_wheel_link"/>
        <axis xyz="0 1 0"/>
    </joint>

    <link name="left_front_wheel_link">
        <visual>
            <origin xyz="0 0 0" rpy="1.5707 0 0" />
            <geometry>
                <cylinder radius="0.06" length = "0.025"/>
            </geometry>
            <material name="white">
                <color rgba="0 1 1 0.9"/>
            </material>
        </visual>
    </link>

    <joint name="right_front_wheel_joint" type="continuous">
        <origin xyz="0.19 -0.19 -0.05" rpy="0 0 0"/>
        <parent link="base_link"/>
        <child link="right_front_wheel_link"/>
        <axis xyz="0 1 0"/>
    </joint>

    <link name="right_front_wheel_link">
        <visual>
            <origin xyz="0 0 0" rpy="1.5707 0 0" />
            <geometry>
                <cylinder radius="0.06" length = "0.025"/>
            </geometry>
            <material name="white">
                <color rgba="0 1 1 0.9"/>
            </material>
        </visual>
    </link>

    <joint name="left_back_wheel_joint" type="continuous">
        <origin xyz="-0.19 0.19 -0.05" rpy="0 0 0"/>
        <parent link="base_link"/>
        <child link="left_back_wheel_link"/>
        <axis xyz="0 1 0"/>
    </joint>

    <link name="left_back_wheel_link">
        <visual>
            <origin xyz="0 0 0" rpy="1.5707 0 0" />
            <geometry>
                <cylinder radius="0.06" length = "0.025"/>
            </geometry>
            <material name="white">
                <color rgba="0 1 1 0.9"/>
            </material>
        </visual>
    </link>

    <joint name="right_back_wheel_joint" type="continuous">
        <origin xyz="-0.19 -0.19 -0.05" rpy="0 0 0"/>
        <parent link="base_link"/>
        <child link="right_back_wheel_link"/>
        <axis xyz="0 1 0"/>
    </joint>

    <link name="right_back_wheel_link">
        <visual>
            <origin xyz="0 0 0" rpy="1.5707 0 0" />
            <geometry>
                <cylinder radius="0.06" length = "0.025"/>
            </geometry>
            <material name="white">
                <color rgba="0 1 1 0.9"/>
            </material>
        </visual>
    </link>

    <joint name="front_caster_joint" type="continuous">
        <origin xyz="0.18 0 -0.095" rpy="0 0 0"/>
        <parent link="base_link"/>
        <child link="front_caster_link"/>
        <axis xyz="0 1 0"/>
    </joint>

    <link name="front_caster_link">
        <visual>
            <origin xyz="0 0 0" rpy="0 0 0"/>
            <geometry>
                <sphere radius="0.015" />
            </geometry>
            <material name="black">
                <color rgba="0 0 0 0.95"/>
            </material>
        </visual>
    </link>

    <joint name="back_caster_joint" type="continuous">
        <origin xyz="-0.18 0 -0.095" rpy="0 0 0"/>
        <parent link="base_link"/>
        <child link="back_caster_link"/>
        <axis xyz="0 1 0"/>
    </joint>

    <link name="back_caster_link">
        <visual>
            <origin xyz="0 0 0" rpy="0 0 0"/>
            <geometry>
                <sphere radius="0.015" />
            </geometry>
            <material name="black">
                <color rgba="0 0 0 0.95"/>
            </material>
        </visual>
    </link>

</robot>
